<!--############################### -->
<!-- ROBOTIC ARM -->
<!--############################### -->

  <!-- ARM BASE -->
  <!-- ==================================== -->
  <joint type="revolute" name="arm_base_joint">
    <origin xyz="0 0 0.1" rpy="0 0 0"/>
    <child link="arm_base_link"/>
    <parent link="mobile_body_link"/>
    <axis xyz="0 0 1" rpy="0 0 0"/>
    <limit effort="100" velocity="100" lower="-${pi}" upper="${pi}"/>
  </joint>

  <xacro:link_cylinder link_name="arm_base_link" radius="${0.135/2}" length="0.2" density="1" mesh_name="package://custom_robot_tutorial/meshes/arm_base_mesh.stl" >
    <!-- origin visual -->
    <origin xyz="0 0 0" rpy="0 0 0"/>
    <!-- origin collision -->
    <origin xyz="0 0 0.1" rpy="0 0 0"/>
    <!-- origin interia -->
    <origin xyz="0 0 0.1" rpy="0 0 0"/>
  </xacro:link_cylinder>

  <!-- LINK 1 -->
  <!-- ==================================== -->
  <joint type="revolute" name="link_1_joint">
    <origin xyz="0 0 0.2" rpy="-${pi/2} 0 0"/>
    <child link="link_1_link"/>
    <parent link="arm_base_link"/>
    <axis xyz="0 0 1" rpy="0 0 0"/>
    <limit effort="100" velocity="100" lower="-${pi/2}" upper="${pi/2}"/>
  </joint>

  <xacro:link_cylinder link_name="link_1_link" radius="${0.075/2}" length="0.385" density="1" mesh_name="package://custom_robot_tutorial/meshes/link_1_mesh.stl" >
    <!-- origin visual -->
    <origin xyz="0 -${0.385/2} 0" rpy="${pi/2} 0 0"/>
    <!-- origin collision -->
    <origin xyz="0 -${0.385/2} 0" rpy="${pi/2} 0 0"/>
    <!-- origin interia -->
    <origin xyz="0 -${0.385/2} 0" rpy="${pi/2} 0 0"/>
  </xacro:link_cylinder>
